Workbook

Sheet Backlog
A1: Order No | B1: Work Item Type | C1: Title | D1: Description | E1: Activity | F1: Estimated Hours
A2: 1 | B2: Epic | C2: KUKA FM Middleware | D2: Middleware between an upstream system and KUKA AMR Fleet Manager: dispatch/cancel missions, sync mission and robot states, web UI. | F2: =SUMIFS(F3:F64,B3:B64,"Task")
A3: 1.1 | B3: Feature | C3: Mission Management | D3: Dispatching, cancelling and monitoring missions created by the middleware (UC1–UC5). | F3: =SUMIFS(F4:F30,B4:B30,"Task")
A4: 1.1.1 | B4: User Story | C4: UC1 Dispatch mission | D4: As an operator I want to dispatch a new RACK_MOVE mission to a selected robot. | F4: =SUMIFS(F5:F9,B5:B9,"Task")
A5: 1.1.1.1 | B5: Task | C5: Endpoint POST /api/missions + input validation | D5: Create POST /api/missions. Validate start node, target node, container code, priority (1–99) and that the robot exists. Return 201 or a validation error. | E5: Backend | F5: 6
A6: 1.1.1.2 | B6: Task | C6: DB: insert mission | D6: Persist the new mission with status 10 (Created), generated mission_code/request_id and robot FK. Write only after KUKA FM confirms success. | E6: Backend | F6: 4
A7: 1.1.1.3 | B7: Task | C7: KUKA FM: submitMission call (RACK_MOVE) | D7: Call submitMission at https://kukafm.its.fei with Authorization token. Build RACK_MOVE body (missionData start/target node, robotIds); other params from appsettings. Handle success=false. | E7: Backend | F7: 6
A8: 1.1.1.4 | B8: Task | C8: Dispatch dialog + robot select | D8: Dialog opened by '+ Dispatch mission' with robot select (robots from DB), start/target node, container code and priority. Show success or error message. | E8: Frontend | F8: 6
A9: 1.1.1.5 | B9: Task | C9: Unit tests for dispatch mission | D9: Unit tests for input validation, KUKA submitMission request mapping and service logic (KUKA client and DB mocked). | E9: Testing | F9: 6
A10: 1.1.2 | B10: User Story | C10: UC2 Cancel mission | D10: As an operator I want to force-cancel a running mission. | F10: =SUMIFS(F11:F15,B11:B15,"Task")
A11: 1.1.2.1 | B11: Task | C11: Endpoint POST /api/missions/{code}/cancel | D11: Create POST /api/missions/{code}/cancel. Return 200 on success, 404 if not found, 409 if mission is not active. | E11: Backend | F11: 4
A12: 1.1.2.2 | B12: Task | C12: DB: load mission + active status check | D12: Load mission by mission_code and check that its status is active (10, 20, 25, 28, 50). | E12: Backend | F12: 2
A13: 1.1.2.3 | B13: Task | C13: KUKA FM: missionCancel call (FORCE) | D13: Call missionCancel with missionCode and cancelMode FORCE. Final status (31 Cancelled) is stored later by mission sync. | E13: Backend | F13: 4
A14: 1.1.2.4 | B14: Task | C14: Cancel button + confirm dialog | D14: Cancel button shown only on active missions; confirmation dialog mentioning FORCE cancel; show result message. | E14: Frontend | F14: 3
A15: 1.1.2.5 | B15: Task | C15: Unit tests for cancel mission | D15: Unit tests for active / not-active / not-found cases and KUKA FM error handling (KUKA client and DB mocked). | E15: Testing | F15: 4
A16: 1.1.3 | B16: User Story | C16: UC3 View mission status | D16: As an operator I want to see the current status of active and finished missions. | F16: =SUMIFS(F17:F20,B17:B20,"Task")
A17: 1.1.3.1 | B17: Task | C17: Endpoint GET /api/missions (active/finished filter) | D17: Create GET /api/missions with optional filter state=active|finished; return missions with status code and name, robot and timestamps. | E17: Backend | F17: 3
A18: 1.1.3.2 | B18: Task | C18: DB: missions query | D18: EF Core query over mission table with status filter, robot join and ordering by created_at desc. | E18: Backend | F18: 2
A19: 1.1.3.3 | B19: Task | C19: Missions table + filter + 1 s polling | D19: Missions table (code, status badge, robot, nodes, container, priority, times) with All/Active/Finished filter and auto-refresh every 1 s. | E19: Frontend | F19: 8
A20: 1.1.3.4 | B20: Task | C20: Unit tests for view mission status | D20: Unit tests for the active/finished filter logic and the missions service. | E20: Testing | F20: 3
A21: 1.1.4 | B21: User Story | C21: UC4 View mission status history | D21: As an operator I want to see all previous statuses of a mission. | F21: =SUMIFS(F22:F25,B22:B25,"Task")
A22: 1.1.4.1 | B22: Task | C22: Endpoint GET /api/missions/{code}/history | D22: Create GET /api/missions/{code}/history returning previous states (status, robot, valid_from, valid_to). | E22: Backend | F22: 2
A23: 1.1.4.2 | B23: Task | C23: DB: mission history query | D23: Query mission_status_history by mission_id ordered by valid_to desc. | E23: Backend | F23: 2
A24: 1.1.4.3 | B24: Task | C24: Show history rows in missions table | D24: 'Show history' checkbox adds grey previous-state rows under each mission. | E24: Frontend | F24: 4
A25: 1.1.4.4 | B25: Task | C25: Unit tests for view mission status history | D25: Unit tests for the mission history service (existing/unknown mission). | E25: Testing | F25: 2
A26: 1.1.5 | B26: User Story | C26: UC5 Synchronize mission status | D26: As the system I want to periodically sync statuses of tracked missions from KUKA FM. | F26: =SUMIFS(F27:F30,B27:B30,"Task")
A27: 1.1.5.1 | B27: Task | C27: Scheduler job for mission sync (interval from appsettings) | D27: Hosted background service running on interval from appsettings; starts only after first robot sync finished; logs to Seq. | E27: Backend | F27: 4
A28: 1.1.5.2 | B28: Task | C28: DB: update mission + write status history | D28: For each changed mission copy previous state into mission_status_history, update status/robot/updated_at; set completed_at for final statuses. | E28: Backend | F28: 4
A29: 1.1.5.3 | B29: Task | C29: KUKA FM: jobQuery call (once per tick) | D29: Call jobQuery once per tick (limit and filters from appsettings) and match results to active missions by jobCode. | E29: Backend | F29: 5
A30: 1.1.5.4 | B30: Task | C30: Unit tests for mission sync | D30: Unit tests for sync logic: status change, no change, final status, unknown jobCode and KUKA FM error. | E30: Testing | F30: 5
A31: 1.2 | B31: Feature | C31: Robot Management | D31: Monitoring robots and their states synchronized from KUKA FM (UC6–UC8). | F31: =SUMIFS(F32:F46,B32:B46,"Task")
A32: 1.2.1 | B32: User Story | C32: UC6 View robot status | D32: As an operator I want to see all robots and their current state. | F32: =SUMIFS(F33:F36,B33:B36,"Task")
A33: 1.2.1.1 | B33: Task | C33: Endpoint GET /api/robots + status mapping (Available/Busy/Offline) | D33: Create GET /api/robots returning robots with KUKA status and mapped state (Idle→Available; Departure/Executing/Charging/Updating→Busy; Offline/Abnormal→Offline). | E33: Backend | F33: 3
A34: 1.2.1.2 | B34: Task | C34: DB: robots query | D34: EF Core query over robot table ordered by robot_code. | E34: Backend | F34: 2
A35: 1.2.1.3 | B35: Task | C35: Robots table + 1 s polling | D35: Robots table (code, type, state badge, KUKA status, battery bar, map, node, mission, updated) with auto-refresh every 1 s. | E35: Frontend | F35: 6
A36: 1.2.1.4 | B36: Task | C36: Unit tests for view robot status | D36: Unit tests for status mapping (Available/Busy/Offline) and the robots service. | E36: Testing | F36: 3
A37: 1.2.2 | B37: User Story | C37: UC7 View robot status history | D37: As an operator I want to see all previous states of a robot. | F37: =SUMIFS(F38:F41,B38:B41,"Task")
A38: 1.2.2.1 | B38: Task | C38: Endpoint GET /api/robots/{id}/history | D38: Create GET /api/robots/{id}/history returning previous states with valid_from/valid_to. | E38: Backend | F38: 2
A39: 1.2.2.2 | B39: Task | C39: DB: robot history query | D39: Query robot_status_history by robot_id ordered by valid_to desc. | E39: Backend | F39: 2
A40: 1.2.2.3 | B40: Task | C40: Show history rows in robots table | D40: 'Show history' checkbox adds grey previous-state rows under each robot. | E40: Frontend | F40: 3
...

Sheet Summary
A1: Estimated hours by Feature
A2: Feature | B2: Hours
A3: Mission Management | B3: =Backlog!F3
A4: Robot Management | B4: =Backlog!F31
A5: Deployment | B5: =Backlog!F47
A6: Total | B6: =SUM(B3:B5)
A8: Estimated hours by Activity
A9: Activity | B9: Hours
A10: Backend | B10: =SUMIFS(Backlog!F:F,Backlog!E:E,"Backend",Backlog!B:B,"Task")
A11: Frontend | B11: =SUMIFS(Backlog!F:F,Backlog!E:E,"Frontend",Backlog!B:B,"Task")
A12: Testing | B12: =SUMIFS(Backlog!F:F,Backlog!E:E,"Testing",Backlog!B:B,"Task")
A13: Deployment | B13: =SUMIFS(Backlog!F:F,Backlog!E:E,"Deployment",Backlog!B:B,"Task")
A14: Total | B14: =SUM(B10:B13)
